Workbook

Sheet SDG Reference
A1: OECS SKIP Component 1.1 — Post-Secondary Data Collection Instrument
A2: SDG Indicator Reference Sheet — Post-Secondary / Tertiary Education
A3: Each indicator listed below is tagged in the relevant data table sheet. Colour coding identifies which tables feed each indicator.
A5: SDG Indicator | B5: Short Title | C5: Metric Type | D5: Numerator | E5: Denominator / Notes | F5: Relevant Sheet(s)
A6: SDG 4.3.2 | B6: Gross Enrolment Ratio — Tertiary | C6: Rate | D6: Total enrolment in tertiary (ISCED 5–8), by sex | E6: Population of 5-year age group after end of secondary schooling, by sex | F6: Enrolment, Age Dis
A7: SDG 4.3.3 | B7: TVET Participation Rate (15–24) | C7: Rate | D7: Enrolment in TVET programmes aged 15–24, by sex | E7: Total population aged 15–24. Flag: age data MUST be collected | F7: Age Dis
A8: SDG 4.5.3 | B8: Equity Funding Mechanisms | C8: Existence (Y/N) | D8: Policy or mechanism to reallocate resources to disadvantaged groups | E8: Binary — Yes/No with supporting description | F8: Finance
A9: SDG 4.5.4 | B9: Expenditure per Student by Level | C9: Currency | D9: Total education expenditure by level and source | E9: Average enrolled students by level | F9: Finance
A10: SDG 4.5.5 | B10: ODA to Education — LDC Share | C10: Percentage | D10: ODA to education in LDCs | E10: Total ODA to education globally. For MoE reporting — flag scholarship funding source | F10: Finance
A11: SDG 4.5.6 | B11: Education Expenditure as % of GDP | C11: Percentage | D11: Government + private + international education expenditure | E11: GDP at market prices. Breakdown by source required | F11: Finance
A12: SDG 4.a.3 | B12: Attacks on Students/Staff/Institutions | C12: Count | D12: Number of reported incidents in academic year | E12: Zero-value is a valid answer — must be reported annually | F12: Background
A13: SDG 4.b.1 | B13: ODA Flows for Scholarships | C13: Currency (USD) | D13: Volume of scholarships received by sector and type of study | E13: Distinguish: Government Scholarship / International ODA / Self-funded | F13: Enrolment, Finance
A14: SDG 4.c.1 | B14: Teachers with Minimum Qualifications | C14: Percentage | D14: Teachers meeting national minimum qualification standard, by level | E14: Total number of teachers in service, by level | F14: Teaching Staff, Staff Profile
A15: SDG 4.c.2 | B15: Pupil-to-Trained-Teacher Ratio | C15: Ratio | D15: Total enrolled pupils | E15: Number of trained teachers | F15: Teaching Staff
A16: SDG 4.c.3 | B16: Qualified Teachers by National Standards | C16: Percentage | D16: Teachers qualified to national standards by type of institution | E16: Total teachers. Separate Full Time / Part Time | F16: Teaching Staff
... A20: SDG 4.c.7 | B20: Teachers Receiving In-Service Training (12 months) | C20: Percentage | D20: Teachers who received CPD in past 12 months, by type | E20: Total teachers. Distinguish: face-to-face / online / blended | F20: Staff Profile
A22: NOTE: SDG 4.1.1 (Minimum Proficiency) applies to primary/lower secondary only — NOT post-secondary. Do not report post-secondary assessment data under SDG 4.1.1. SDG 4.a.1 (Facilities: water, sanitation, electricity, handwashing, internet) is captured in the Finance sheet.

Sheet Institution Registry
A1: ID | B1: Name | C1: Region | D1: Country | E1: Contact Information
A2: 11111 | B2: Your Institution | C2: Your Region
A3: 22222 | B3: Other Institution | C3: Other Region

Sheet Calculations
A2: Row Labels | B2: Count of Year
A3: Female | B3: 2
A4: Male | B4: 1

Sheet Student Registry
A1: RULI | B1: Local ID | C1: First Name | D1: Other Name | E1: Last Name | F1: Maiden Name | G1: Date of Birth | H1: Gender | I1: Last Updated | J1: Is FTE | K1: Year | L1: Age at Time of Reporting
A2: 683315579 | B2: s11111 | C2: First Student Name | D2: First Student Other Name | E2: First Student Last Name | G2: 39519 | H2: Female | J2: Y | K2: 1 | L2: =(Background!$B$6-YEAR('Student Registry'!G2)) -> 17
A3: 128766605 | B3: s11112 | C3: Other Student First Name | E3: Other Student Last Name | G3: 38629 | H3: Female | J3: N | K3: 1 | L3: =(Background!$B$6-YEAR('Student Registry'!G3)) -> 20
A4: 768489272 | B4: s11113 | C4: Unique Student First Name | E4: Unique Student Last Name | G4: 38827 | H4: Male | J4: N | K4: 2 | L4: =(Background!$B$6-YEAR('Student Registry'!G4)) -> 19

Sheet Definitions
A1: Definitions
A2: Explanatory Notes for Completing the Questionnaire
A5: Term | B5: Definition
A6: Age | B6: Age as of last birthday.
A7: Completed Certified | B7: Student completed a programme and received certification.
A8: Completed Uncertified | B8: Student completed a programme without receiving certification.
A9: CVQ | B9: Caribbean Vocational Qualification.
A10: Date Established | B10: Date the institution first admitted students.
A11: Division | B11: Department of institution providing specific programmes (e.g. Division of Health).
A12: Dropout | B12: Student who leaves before graduation/completion for any reason.
A13: ISCED | B13: International Standard Classification of Education. Post-secondary = ISCED 5–8.
A14: NREN | B14: National Research and Education Network.
A15: Trained Teacher | B15: One who has successfully completed a recognised course of teacher education.
A16: ODA | B16: Official Development Assistance — relevant for SDG 4.b.1 scholarship flows.
... A19: TVET | B19: Technical and Vocational Education and Training — relevant for SDG 4.3.3.

Sheet Teacher Registry
A1: ID | B1: No. | C1: First Name | D1: Other Name | E1: Surname | F1: Maiden Name | G1: Date of Birth | H1: Sex | I1: Last Updated | K1: Age at Time of Reporting | L1: Classification (PR/VP/HOD/TT) | M1: Teacher Type | N1: Subject(s) Taught | O1: Total Periods Taught | P1: Years Teaching Experience | Q1: Nationality | R1: Highest Qualification | S1: Area of Specialisation | T1: CPD Hours Past Year [SDG 4.c.7] | U1: Appraised Last Year? (Y/N) | V1: Left Service This Year? [SDG 4.c.6]
A2: 699493567 | B2: t11111 | C2: First Teacher Name | D2: First Teacher Other Name | E2: First Teacher Last Name | G2: 36597 | H2: Female | K2: =(Background!$B$6-YEAR('Teacher Registry'!G2)) -> 25 | L2: HOD | M2: TT | N2: Spanish | O2: 35 | P2: 12 | Q2: GND | R2: BSc | S2: Computing | T2: 16 | U2: No | V2: No
A3: 699033694 | B3: t11112 | C3: Other Teacher First Name | E3: Other Teacher Last Name | G3: 35342 | H3: Female | K3: =(Background!$B$6-YEAR('Teacher Registry'!G3)) -> 29 | L3: TT | M3: TT | N3: English | O3: 25 | P3: 13
A4: 379804210 | B4: t11113 | C4: Unique Teacher First Name | E4: Unique Teacher Last Name | G4: 29331 | H4: Male | K4: =(Background!$B$6-YEAR('Teacher Registry'!G4)) -> 45 | L4: PR | M4: PR | N4: German | O4: 20 | P4: 25

Sheet Enrolments
A1: Programme Name | B1: Student Name | C1: Teacher Name | D1: Role | E1: Start Date | F1: End Date | G1: Certification Type | H1: Year
A2: Prog 1 | B2: First Student Name | D2: =IF(ISBLANK(C2),"Student","Teacher") -> Student | E2: 45934 | F2: 46057 | G2: =VLOOKUP(A2,'Course Registry'!$A$2:$C$21,2,TRUE) -> Certificate | H2: =VLOOKUP(B2,'Student Registry'!C2:L12,9,FALSE) -> 1
A3: Prog 1 | C3: First Teacher Last Name | D3: =IF(ISBLANK(C3),"Student","Teacher") -> Teacher | E3: 45934 | F3: 46057 | G3: =VLOOKUP(A3,'Course Registry'!$A$2:$C$21,2,TRUE) -> Certificate | H3: 1
A4: Prog 1 | B4: Other Student First Name | D4: =IF(ISBLANK(C4),"Student","Teacher") -> Student | E4: 45965 | F4: 46085 | G4: =VLOOKUP(A4,'Course Registry'!$A$2:$C$21,2,TRUE) -> Certificate | H4: 1
A5: Prog 1 | B5: Unique Student First Name | G5: =VLOOKUP(A5,'Course Registry'!$A$2:$C$21,2,TRUE) -> Certificate | H5: 2

Sheet Course Registry
A1: Programme | B1: Division/Department | C1: Certification | D1: Is Accredited | E1: Is TVET | F1: Programme ID | G1: Enrolment Year 1 | H1: Enrolment Year 2 | I1: Enrolment Year 3 | J1: Enrolment Year 4
A2: Prog 1 | B2: Certificate | C2: Certificate | D2: No | E2: Y | F2: 1 | G2: 40 | H2: 30 | I2: 20 | J2: 10
A3: Prog 2 | B3: Certificate | C3: Certificate | D3: No | E3: Y | F3: =F2+1 -> 2 | G3: 41.983597 | H3: 18.208511 | I3: 59.902477 | J3: 48.641849
A4: Prog 3 | B4: Certificate | C4: Certificate | D4: No | E4: Y | F4: =F3+1 -> 3 | G4: 24.093908 | H4: 41.724611 | I4: 52.246793 | J4: 36.446529
A5: Prog 4 | B5: Certificate | C5: Certificate | D5: No | E5: Y | F5: =F4+1 -> 4 | G5: 56.286862 | H5: 57.922321 | I5: 28.893391 | J5: 59.955918
A6: Prog 5 | B6: CAPE | C6: CAPE | D6: No | E6: N | F6: =F5+1 -> 5 | G6: 39.541933 | H6: 10.53868 | I6: 47.205665 | J6: 15.904098
A7: Prog 6 | B7: CAPE | C7: CAPE | D7: No | E7: N | F7: =F6+1 -> 6 | G7: 50.96248 | H7: 35.534736 | I7: 44.377167 | J7: 45.336109
A8: Prog 7 | B8: CAPE | C8: CAPE | D8: No | E8: N | F8: =F7+1 -> 7 | G8: 13.593626 | H8: 48.843525 | I8: 10.306104 | J8: 39.16569
A9: Prog 8 | B9: CAPE | C9: CAPE | D9: No | E9: N | F9: =F8+1 -> 8 | G9: 57.119392 | H9: 25.804483 | I9: 14.580305 | J9: 16.823469
A10: Prog 9 | B10: Associate Degree | C10: Associate Degree | D10: No | E10: N | F10: =F9+1 -> 9 | G10: 57.6828 | H10: 52.711989 | I10: 53.637379 | J10: 23.185164
A11: Prog 10 | B11: Associate Degree | C11: Associate Degree | D11: No | E11: N | F11: =F10+1 -> 10 | G11: 47.121038 | H11: 41.949405 | I11: 37.465116 | J11: 22.388902
A12: Prog 11 | B12: Associate Degree | C12: Associate Degree | D12: No | E12: N | F12: =F11+1 -> 11 | G12: 59.369878 | H12: 50.099701 | I12: 23.627326 | J12: 28.267776
A13: Prog 12 | B13: Associate Degree | C13: Associate Degree | D13: No | E13: N | F13: =F12+1 -> 12 | G13: 13.185084 | H13: 27.24308 | I13: 25.16176 | J13: 18.520224
A14: Prog 13 | B14: Undergraduate Degree | C14: Undergraduate Degree | D14: No | E14: N | F14: =F13+1 -> 13 | G14: 54.552184 | H14: 51.257796 | I14: 10.259009 | J14: 21.438089
... A21: Prog 20 | B21: Stand Alone Academic Courses | C21: Stand Alone Academic Courses | D21: Regionally | E21: N | F21: =F20+1 -> 20 | G21: 31.311939 | H21: 19.894146 | I21: 11.087505 | J21: 32.747477

Sheet Cover
A1: OECS MEMBER STATE — MINISTRY OF EDUCATION
A2: POST-SECONDARY / TERTIARY QUESTIONNAIRE | 2025–2026 ACADEMIC YEAR
A3: SDG-Tagged Edition — each table identifies which SDG 4 indicator it feeds
A5: INSTRUCTIONS
A6: 1. All data should refer to 15th October 2025. Return completed questionnaire to XXXX by XXXX.
A7: 2. Refer to definitions on the Definitions sheet before completing. Contact XXXX for assistance.
A8: Institution:
A9: Date completed:
A10: Name of completing officer:
A11: Signature:
A12: FOR OFFICIAL USE ONLY
A13: Date received:
A14: Status: | B14: Complete ☐ Incomplete ☐
A15: Action taken: | B15: Accept ☐ Return ☐ Consult ☐
A16: SDG DATA NOTE
A17: This questionnaire has been updated to tag each data table with the SDG 4 indicator(s) it feeds. The SDG Reference sheet at the front of this workbook provides the full indicator definitions. Colour-coded tags appear in each table header — match the colour key on the SDG Reference sheet.

Sheet Background
A1: SECTION 1: BACKGROUND INFORMATION
A2: Post-Secondary/Tertiary Questionnaire — 2025/2026
A3: SDG tags indicate which indicators this section feeds
A6: Academic Year - October 15 | B6: 2025 | C6: to September 14 | D6: =B6+1 -> 2026
A7: Name of Institution:
A8: 1.1 Mailing Address:
A9: 1.2 Date Established: | C9: 1.3 Phone No.:
A10: 1.4 Fax No.: | C10: 1.5 E-mail:
A11: 1.6 Website: | C11: 1.7 Name of Dean/Principal:
A12: 1.8 Management Type
A13: Ministry of Education ☐ | B13: Board/Council ☐ | C13: Other ☐
A14: 1.9 – 1.11 Staffing and Enrolment
A15: 1.9 Non-Teaching Staff: | C15: 1.10 Teaching Staff: | E15: 1.11 Total Enrolment:
A17: 1.12 Enrolment by Division and Gender
A18: Division Name | B18: Male | C18: Female | D18: Total
A25: 1.13 – 1.18 Strategic Plan, Safety, and Infrastructure
A26: 1.13 Does the institution have a strategic plan? | B26: Yes ☐ | C26: No ☐ | G26: SDG —
A27: 1.14 Does the institution have a Disaster Management Plan? | B27: Yes ☐ | C27: No ☐ | G27: SDG 4.a.3
A28: 1.15 Emergency drills conducted in past year — how many? | B28: Yes ☐ | C28: No ☐ | G28: SDG 4.a.3
A29: 1.16 Are all areas accessible to students with disabilities? | B29: Yes ☐ | C29: No ☐ | G29: SDG 4.a.1
A30: 1.17 Is the institution a member of the OECS NREN? | B30: Yes ☐ | C30: No ☐ | G30: SDG 4.a.1
A31: 1.18 Number of teaching staff undertaking academic research (M / F) | B31: Yes ☐ | C31: No ☐ | G31: SDG 4.c.1

Sheet Enrolment
A1: T2. CURRENT ENROLMENT BY DIVISION/DEPARTMENT, PROGRAMME, AND SEX
A2: SDG 4.3.2 — Tertiary GER | SDG 4.3.3 — TVET Participation | SDG 4.b.1 — Scholarship Enrolment
A3: Complete one block per Division. Copy and paste rows as needed.
A4: SDG INDICATOR COLOUR KEY — tagged cells show which SDG each data element supports
A5: SDG 4.3.2 — Tertiary GER | B5: SDG 4.3.3 — TVET Participation | C5: SDG 4.5.x — Equity & Finance | D5: SDG 4.a.3 — Safety | E5: SDG 4.b.1 — ODA/Scholarships | F5: SDG 4.c.x — Teachers/CPD | G5: SDG 4.a.1 — Facilities
A6: SDG 4.3.2 Tertiary GER | B6: SDG 4.3.3 TVET Participation | C6: SDG 4.b.1 Scholarship Enrolment | D6: SDG 4.5.1 Parity (M/F)
A7: Division/Department | B7: Certification | C7: Programme | D7: Accredited? (No/Locally/ Regionally/ Internationally) | E7: Is TVET? (Y/N) → SDG 4.3.3 | F7: Year 1 M | G7: Year 1 F | H7: Year 2 M | I7: Year 2 F | J7: Year 3 M | K7: Year 3 F | L7: Year 4 M | M7: Year 4 F | N7: Total PT M | O7: Total PT F | P7: Total FT M | Q7: Total FT F | R7: OECS Nationals M | S7: OECS Nationals F | T7: Other CARICOM M | U7: Other CARICOM F | V7: Other Nationality M | W7: Other Nationality F | X7: ODA Scholarship (SDG 4.b.1)
A8: =VLOOKUP(Enrolment!C8,'Course Registry'!$A$2:$F$21,2,FALSE) -> Certificate | B8: =VLOOKUP(Enrolment!C8,'Course Registry'!$A$2:$F$21,2,FALSE) -> Certificate | C8: Prog 1 | D8: =VLOOKUP(Enrolment!C8,'Course Registry'!$A$2:$F$21,4,FALSE) -> No | E8: =VLOOKUP(Enrolment!C8,'Course Registry'!$A$2:$F$21,5,FALSE) -> Y | F8: 0 | G8: 0 | H8: 0 | I8: 0 | J8: 0 | K8: 0 | L8: 0 | M8: 0 | N8: 0 | O8: 0 | P8: 0 | Q8: 0 | R8: 0 | S8: 0 | T8: 0 | U8: 0 | V8: 0 | W8: 0 | X8: 0
A9: =VLOOKUP(Enrolment!C9,'Course Registry'!$A$2:$F$21,2,FALSE) -> Certificate | B9: =VLOOKUP(Enrolment!C9,'Course Registry'!$A$2:$F$21,2,FALSE) -> Certificate | C9: Prog 2 | D9: =VLOOKUP(Enrolment!C9,'Course Registry'!$A$2:$F$21,4,FALSE) -> No | E9: =VLOOKUP(Enrolment!C9,'Course Registry'!$A$2:$F$21,5,FALSE) -> Y | F9: 0 | G9: 0 | H9: 0 | I9: 0 | J9: 0 | K9: 0 | L9: 0 | M9: 0 | N9: 0 | O9: 0 | P9: 0 | Q9: 0 | R9: 0 | S9: 0 | T9: 0 | U9: 0 | V9: 0 | W9: 0 | X9: 0
A10: =VLOOKUP(Enrolment!C10,'Course Registry'!$A$2:$F$21,2,FALSE) -> Certificate | B10: =VLOOKUP(Enrolment!C10,'Course Registry'!$A$2:$F$21,2,FALSE) -> Certificate | C10: Prog 3 | D10: =VLOOKUP(Enrolment!C10,'Course Registry'!$A$2:$F$21,4,FALSE) -> No | E10: =VLOOKUP(Enrolment!C10,'Course Registry'!$A$2:$F$21,5,FALSE) -> Y | F10: 0 | G10: 0 | H10: 0 | I10: 0 | J10: 0 | K10: 0 | L10: 0 | M10: 0 | N10: 0 | O10: 0 | P10: 0 | Q10: 0 | R10: 0 | S10: 0 | T10: 0 | U10: 0 | V10: 0 | W10: 0 | X10: 0
A11: =VLOOKUP(Enrolment!C11,'Course Registry'!$A$2:$F$21,2,FALSE) -> Certificate | B11: =VLOOKUP(Enrolment!C11,'Course Registry'!$A$2:$F$21,2,FALSE) -> Certificate | C11: Prog 4 | D11: =VLOOKUP(Enrolment!C11,'Course Registry'!$A$2:$F$21,4,FALSE) -> No | E11: =VLOOKUP(Enrolment!C11,'Course Registry'!$A$2:$F$21,5,FALSE) -> Y | F11: 0 | G11: 0 | H11: 0 | I11: 0 | J11: 0 | K11: 0 | L11: 0 | M11: 0 | N11: 0 | O11: 0 | P11: 0 | Q11: 0 | R11: 0 | S11: 0 | T11: 0 | U11: 0 | V11: 0 | W11: 0 | X11: 0
A12: =VLOOKUP(Enrolment!C12,'Course Registry'!$A$2:$F$21,2,FALSE) -> CAPE | B12: =VLOOKUP(Enrolment!C12,'Course Registry'!$A$2:$F$21,2,FALSE) -> CAPE | C12: Prog 5 | D12: =VLOOKUP(Enrolment!C12,'Course Registry'!$A$2:$F$21,4,FALSE) -> No | E12: =VLOOKUP(Enrolment!C12,'Course Registry'!$A$2:$F$21,5,FALSE) -> N | F12: 0 | G12: 0 | H12: 0 | I12: 0 | J12: 0 | K12: 0 | L12: 0 | M12: 0 | N12: 0 | O12: 0 | P12: 0 | Q12: 0 | R12: 0 | S12: 0 | T12: 0 | U12: 0 | V12: 0 | W12: 0 | X12: 0
A13: =VLOOKUP(Enrolment!C13,'Course Registry'!$A$2:$F$21,2,FALSE) -> CAPE | B13: =VLOOKUP(Enrolment!C13,'Course Registry'!$A$2:$F$21,2,FALSE) -> CAPE | C13: Prog 6 | D13: =VLOOKUP(Enrolment!C13,'Course Registry'!$A$2:$F$21,4,FALSE) -> No | E13: =VLOOKUP(Enrolment!C13,'Course Registry'!$A$2:$F$21,5,FALSE) -> N | F13: 0 | G13: 0 | H13: 0 | I13: 0 | J13: 0 | K13: 0 | L13: 0 | M13: 0 | N13: 0 | O13: 0 | P13: 0 | Q13: 0 | R13: 0 | S13: 0 | T13: 0 | U13: 0 | V13: 0 | W13: 0 | X13: 0
A14: =VLOOKUP(Enrolment!C14,'Course Registry'!$A$2:$F$21,2,FALSE) -> CAPE | B14: =VLOOKUP(Enrolment!C14,'Course Registry'!$A$2:$F$21,2,FALSE) -> CAPE | C14: Prog 7 | D14: =VLOOKUP(Enrolment!C14,'Course Registry'!$A$2:$F$21,4,FALSE) -> No | E14: =VLOOKUP(Enrolment!C14,'Course Registry'!$A$2:$F$21,5,FALSE) -> N | F14: 0 | G14: 0 | H14: 0 | I14: 0 | J14: 0 | K14: 0 | L14: 0 | M14: 0 | N14: 0 | O14: 0 | P14: 0 | Q14: 0 | R14: 0 | S14: 0 | T14: 0 | U14: 0 | V14: 0 | W14: 0 | X14: 0
A15: =VLOOKUP(Enrolment!C15,'Course Registry'!$A$2:$F$21,2,FALSE) -> CAPE | B15: =VLOOKUP(Enrolment!C15,'Course Registry'!$A$2:$F$21,2,FALSE) -> CAPE | C15: Prog 8 | D15: =VLOOKUP(Enrolment!C15,'Course Registry'!$A$2:$F$21,4,FALSE) -> No | E15: =VLOOKUP(Enrolment!C15,'Course Registry'!$A$2:$F$21,5,FALSE) -> N | F15: 0 | G15: 0 | H15: 0 | I15: 0 | J15: 0 | K15: 0 | L15: 0 | M15: 0 | N15: 0 | O15: 0 | P15: 0 | Q15: 0 | R15: 0 | S15: 0 | T15: 0 | U15: 0 | V15: 0 | W15: 0 | X15: 0
A16: =VLOOKUP(Enrolment!C16,'Course Registry'!$A$2:$F$21,2,FALSE) -> Associate Degree | B16: =VLOOKUP(Enrolment!C16,'Course Registry'!$A$2:$F$21,2,FALSE) -> Associate Degree | C16: Prog 9 | D16: =VLOOKUP(Enrolment!C16,'Course Registry'!$A$2:$F$21,4,FALSE) -> No | E16: =VLOOKUP(Enrolment!C16,'Course Registry'!$A$2:$F$21,5,FALSE) -> N | F16: 0 | G16: 0 | H16: 0 | I16: 0 | J16: 0 | K16: 0 | L16: 0 | M16: 0 | N16: 0 | O16: 0 | P16: 0 | Q16: 0 | R16: 0 | S16: 0 | T16: 0 | U16: 0 | V16: 0 | W16: 0 | X16: 0
A17: =VLOOKUP(Enrolment!C17,'Course Registry'!$A$2:$F$21,2,FALSE) -> Associate Degree | B17: =VLOOKUP(Enrolment!C17,'Course Registry'!$A$2:$F$21,2,FALSE) -> Associate Degree | C17: Prog 10 | D17: =VLOOKUP(Enrolment!C17,'Course Registry'!$A$2:$F$21,4,FALSE) -> No | E17: =VLOOKUP(Enrolment!C17,'Course Registry'!$A$2:$F$21,5,FALSE) -> N | F17: 0 | G17: 0 | H17: 0 | I17: 0 | J17: 0 | K17: 0 | L17: 0 | M17: 0 | N17: 0 | O17: 0 | P17: 0 | Q17: 0 | R17: 0 | S17: 0 | T17: 0 | U17: 0 | V17: 0 | W17: 0 | X17: 0
A18: =VLOOKUP(Enrolment!C18,'Course Registry'!$A$2:$F$21,2,FALSE) -> Associate Degree | B18: =VLOOKUP(Enrolment!C18,'Course Registry'!$A$2:$F$21,2,FALSE) -> Associate Degree | C18: Prog 11 | D18: =VLOOKUP(Enrolment!C18,'Course Registry'!$A$2:$F$21,4,FALSE) -> No | E18: =VLOOKUP(Enrolment!C18,'Course Registry'!$A$2:$F$21,5,FALSE) -> N | F18: 0 | G18: 0 | H18: 0 | I18: 0 | J18: 0 | K18: 0 | L18: 0 | M18: 0 | N18: 0 | O18: 0 | P18: 0 | Q18: 0 | R18: 0 | S18: 0 | T18: 0 | U18: 0 | V18: 0 | W18: 0 | X18: 0
A19: =VLOOKUP(Enrolment!C19,'Course Registry'!$A$2:$F$21,2,FALSE) -> Associate Degree | B19: =VLOOKUP(Enrolment!C19,'Course Registry'!$A$2:$F$21,2,FALSE) -> Associate Degree | C19: Prog 12 | D19: =VLOOKUP(Enrolment!C19,'Course Registry'!$A$2:$F$21,4,FALSE) -> No | E19: =VLOOKUP(Enrolment!C19,'Course Registry'!$A$2:$F$21,5,FALSE) -> N | F19: 0 | G19: 0 | H19: 0 | I19: 0 | J19: 0 | K19: 0 | L19: 0 | M19: 0 | N19: 0 | O19: 0 | P19: 0 | Q19: 0 | R19: 0 | S19: 0 | T19: 0 | U19: 0 | V19: 0 | W19: 0 | X19: 0
... A27: =VLOOKUP(Enrolment!C27,'Course Registry'!$A$2:$F$21,2,FALSE) -> Stand Alone Academic Courses | B27: =VLOOKUP(Enrolment!C27,'Course Registry'!$A$2:$F$21,2,FALSE) -> Stand Alone Academic Courses | C27: Prog 20 | D27: =VLOOKUP(Enrolment!C27,'Course Registry'!$A$2:$F$21,4,FALSE) -> Regionally | E27: =VLOOKUP(Enrolment!C27,'Course Registry'!$A$2:$F$21,5,FALSE) -> N | F27: 0 | G27: 0 | H27: 0 | I27: 0 | J27: 0 | K27: 0 | L27: 0 | M27: 0 | N27: 0 | O27: 0 | P27: 0 | Q27: 0 | R27: 0 | S27: 0 | T27: 0 | U27: 0 | V27: 0 | W27: 0 | X27: 0

Sheet Age Dis
A1: T3. ENROLMENT BY AGE, PROGRAMME, AND SEX
A2: SDG 4.3.2 — Tertiary GER | SDG 4.3.3 — TVET Participation Rate (ages 15–24 REQUIRED for SDG 4.3.3) | F2: SDG 4.c.x — Teachers/CPD | G2: SDG 4.a.1 — Facilities
A3: CRITICAL: Age disaggregation for 15–24 is mandatory for SDG 4.3.3 calculation.
A6: SDG 4.3.2 Tertiary GER (all ages) | B6: SDG 4.3.3 TVET 15–24 ★ MANDATORY AGE BAND | C6: SDG 4.5.1 Parity (M/F breakdown) | D6: SDG 4.b.1 Scholarship by age if available
A7: Age as of 15th October | B7: Certificate Full Time | D7: CAPE Full Time | F7: Diploma Full Time | H7: Associate Degree Full Time | J7: Bachelors Full Time | L7: Masters Full Time | N7: PhD Full Time | P7: Total M | Q7: Total F
B8: M | C8: F | D8: M | E8: F | F8: M | G8: F | H8: M | I8: F | J8: M | K8: F | L8: M | M8: F | N8: M | O8: F
A9: <16 | B9: 0 | C9: 0 | D9: 0 | E9: 0 | F9: 0 | G9: 0 | H9: 0 | I9: 0 | J9: 0 | K9: 0 | L9: 0 | M9: 0 | N9: 0 | O9: 0 | P9: 0 | Q9: 0
A10: 16 | B10: 0 | C10: 0 | D10: 0 | E10: 0 | F10: 0 | G10: 0 | H10: 0 | I10: 0 | J10: 0 | K10: 0 | L10: 0 | M10: 0 | N10: 0 | O10: 0 | P10: 0 | Q10: 0 | R10: ← SDG 4.3.3
A11: 17 | B11: 0 | C11: 0 | D11: 0 | E11: 0 | F11: 0 | G11: 0 | H11: 0 | I11: 0 | J11: 0 | K11: 0 | L11: 0 | M11: 0 | N11: 0 | O11: 0 | P11: 0 | Q11: 0 | R11: ← SDG 4.3.3
A12: 18 | B12: 0 | C12: 0 | D12: 0 | E12: 0 | F12: 0 | G12: 0 | H12: 0 | I12: 0 | J12: 0 | K12: 0 | L12: 0 | M12: 0 | N12: 0 | O12: 0 | P12: 0 | Q12: 0 | R12: ← SDG 4.3.3
A13: 19 | B13: 0 | C13: 0 | D13: 0 | E13: 0 | F13: 0 | G13: 0 | H13: 0 | I13: 0 | J13: 0 | K13: 0 | L13: 0 | M13: 0 | N13: 0 | O13: 0 | P13: 0 | Q13: 0 | R13: ← SDG 4.3.3
A14: 20 | B14: 0 | C14: 0 | D14: 0 | E14: 0 | F14: 0 | G14: 0 | H14: 0 | I14: 0 | J14: 0 | K14: 0 | L14: 0 | M14: 0 | N14: 0 | O14: 0 | P14: 0 | Q14: 0 | R14: ← SDG 4.3.3
A15: 21 | B15: 0 | C15: 0 | D15: 0 | E15: 0 | F15: 0 | G15: 0 | H15: 0 | I15: 0 | J15: 0 | K15: 0 | L15: 0 | M15: 0 | N15: 0 | O15: 0 | P15: 0 | Q15: 0 | R15: ← SDG 4.3.3
A16: 22 | B16: 0 | C16: 0 | D16: 0 | E16: 0 | F16: 0 | G16: 0 | H16: 0 | I16: 0 | J16: 0 | K16: 0 | L16: 0 | M16: 0 | N16: 0 | O16: 0 | P16: 0 | Q16: 0 | R16: ← SDG 4.3.3
A17: 23 | B17: 0 | C17: 0 | D17: 0 | E17: 0 | F17: 0 | G17: 0 | H17: 0 | I17: 0 | J17: 0 | K17: 0 | L17: 0 | M17: 0 | N17: 0 | O17: 0 | P17: 0 | Q17: 0 | R17: ← SDG 4.3.3
A18: 24 | B18: 0 | C18: 0 | D18: 0 | E18: 0 | F18: 0 | G18: 0 | H18: 0 | I18: 0 | J18: 0 | K18: 0 | L18: 0 | M18: 0 | N18: 0 | O18: 0 | P18: 0 | Q18: 0 | R18: ← SDG 4.3.3
A19: 25 | B19: 0 | C19: 0 | D19: 0 | E19: 0 | F19: 0 | G19: 0 | H19: 0 | I19: 0 | J19: 0 | K19: 0 | L19: 0 | M19: 0 | N19: 0 | O19: 0 | P19: 0 | Q19: 0
A20: 26 | B20: 0 | C20: 0 | D20: 0 | E20: 0 | F20: 0 | G20: 0 | H20: 0 | I20: 0 | J20: 0 | K20: 0 | L20: 0 | M20: 0 | N20: 0 | O20: 0 | P20: 0 | Q20: 0
A21: 27 | B21: 0 | C21: 0 | D21: 0 | E21: 0 | F21: 0 | G21: 0 | H21: 0 | I21: 0 | J21: 0 | K21: 0 | L21: 0 | M21: 0 | N21: 0 | O21: 0 | P21: 0 | Q21: 0
A22: 28 | B22: 0 | C22: 0 | D22: 0 | E22: 0 | F22: 0 | G22: 0 | H22: 0 | I22: 0 | J22: 0 | K22: 0 | L22: 0 | M22: 0 | N22: 0 | O22: 0 | P22: 0 | Q22: 0
A23: 29 | B23: 0 | C23: 0 | D23: 0 | E23: 0 | F23: 0 | G23: 0 | H23: 0 | I23: 0 | J23: 0 | K23: 0 | L23: 0 | M23: 0 | N23: 0 | O23: 0 | P23: 0 | Q23: 0
A24: 30-34 | B24: 0 | C24: 0 | D24: 0 | E24: 0 | F24: 0 | G24: 0 | H24: 0 | I24: 0 | J24: 0 | K24: 0 | L24: 0 | M24: 0 | N24: 0 | O24: 0 | P24: 0 | Q24: 0
A25: 35-39 | B25: 0 | C25: 0 | D25: 0 | E25: 0 | F25: 0 | G25: 0 | H25: 0 | I25: 0 | J25: 0 | K25: 0 | L25: 0 | M25: 0 | N25: 0 | O25: 0 | P25: 0 | Q25: 0
A26: 40 & over | B26: 0 | C26: 0 | D26: 0 | E26: 0 | F26: 0 | G26: 0 | H26: 0 | I26: 0 | J26: 0 | K26: 0 | L26: 0 | M26: 0 | N26: 0 | O26: 0 | P26: 0 | Q26: 0
A27: Age unknown | B27: 0 | C27: 0 | D27: 0 | E27: 0 | F27: 0 | G27: 0 | H27: 0 | I27: 0 | J27: 0 | K27: 0 | L27: 0 | M27: 0 | N27: 0 | O27: 0 | P27: 0 | Q27: 0
A28: Total | B28: 0 | C28: 0 | D28: 0 | E28: 0 | F28: 0 | G28: 0 | H28: 0 | I28: 0 | J28: 0 | K28: 0 | L28: 0 | M28: 0 | N28: 0 | O28: 0 | P28: 0 | Q28: 0

Sheet Leavers
A1: T4–T7. LEAVERS, DROPOUT REASONS, SPECIAL NEEDS, AND GRADUATES
A2: SDG 4.3.2 — Completion feeds GER denominator | SDG 4.5.1 — Disability data | G2: SDG 4.a.1 — Facilities
A6: T4. Leavers for Previous Academic Year by Division, Level and Sex (Full Time)
A7: SDG 4.3.2 Completion | B7: SDG 4.5.1 Parity (M/F)
A8: Type | B8: Level | C8: Sex | D8: Count | E8: Total
A9: Dropouts | B9: Year 1 | C9: M | D9: 0
C10: F | D10: 0
B11: Year 2 | C11: M | D11: 0
C12: F | D12: 0
B13: Year 3 | C13: M | D13: 0
C14: F | D14: 0
A15: Repeaters | B15: Year 1 | C15: M | D15: 0
C16: F | D16: 0
B17: Year 2 | C17: M | D17: 0
C18: F | D18: 0
B19: Year 3 | C19: M | D19: 0
C20: F | D20: 0
A21: Transfers (from) | B21: Year 1 | C21: M | D21: 0
C22: F | D22: 0
B23: Year 2 | C23: M | D23: 0
C24: F | D24: 0
B25: Year 3 | C25: M | D25: 0
C26: F | D26: 0
A27: Completed Certified | B27: Year 1 | C27: M | D27: 0
C28: F | D28: 0
B29: Year 2 | C29: M | D29: 0
C30: F | D30: 0
B31: Year 3 | C31: M | D31: 0
C32: F | D32: 0
A33: Completed Uncertified | B33: Year 1 | C33: M | D33: 0
C34: F | D34: 0
B35: Year 2 | C35: M | D35: 0
C36: F | D36: 0
B37: Year 3 | C37: M | D37: 0
C38: F | D38: 0
A40: T5. Main Reasons for Dropping Out
A41: Migration | B41: ☐ Check if applicable
A42: Withdrawal | B42: ☐ Check if applicable
A43: Expulsion | B43: ☐ Check if applicable
A44: Financial Difficulties | B44: ☐ Check if applicable
...

Sheet Teaching Staff
A1: T8–T9. TEACHING STAFF BY QUALIFICATION AND SEX (FULL TIME AND PART TIME)
A2: SDG 4.c.1 — Proportion with minimum qualifications | SDG 4.c.2 — Pupil-trained teacher ratio | SDG 4.c.3 — % qualified by institution type | SDG 4.c.4 — Pupil-qualified teacher ratio
A3: BOTH full-time and part-time tables must be completed for SDG 4.c calculations.
A6: T8. FULL TIME Teaching Staff by Highest Qualification and Sex
A7: SDG 4.c.1 Min. qualified | B7: SDG 4.c.2/4.c.4 Pupil-teacher ratios | C7: SDG 4.c.3 % qualified by institution type | D7: SDG 4.c.5 Salary data in Finance sheet | E7: SDG 4.c.6 Attrition in Staff Profile | F7: SDG 4.c.7 CPD training in Staff Profile
A8: Division | B8: Ph.D | D8: Masters Degree | F8: Post Grad. Diploma | H8: Bachelors Degree | J8: Associate Degree | L8: Diploma | N8: Certificate | P8: CAPE/A-Levels | R8: Total M | S8: Total F | T8: Total Trained M | U8: Total Trained F
B9: M | C9: F | D9: M | E9: F | F9: M | G9: F | H9: M | I9: F | J9: M | K9: F | L9: M | M9: F | N9: M | O9: F | P9: M | Q9: F
A10: Division … | B10: 0 | C10: 0 | D10: 0 | E10: 0 | F10: 0 | G10: 0 | H10: 0 | I10: 0 | J10: 0 | K10: 0 | L10: 0 | M10: 0 | N10: 0 | O10: 0 | P10: 0 | Q10: 0 | R10: 0 | S10: 0 | T10: 0 | U10: 0
A11: Division … | B11: 0 | C11: 0 | D11: 0 | E11: 0 | F11: 0 | G11: 0 | H11: 0 | I11: 0 | J11: 0 | K11: 0 | L11: 0 | M11: 0 | N11: 0 | O11: 0 | P11: 0 | Q11: 0 | R11: 0 | S11: 0 | T11: 0 | U11: 0
A12: Division … | B12: 0 | C12: 0 | D12: 0 | E12: 0 | F12: 0 | G12: 0 | H12: 0 | I12: 0 | J12: 0 | K12: 0 | L12: 0 | M12: 0 | N12: 0 | O12: 0 | P12: 0 | Q12: 0 | R12: 0 | S12: 0 | T12: 0 | U12: 0
A13: Total | B13: 0 | C13: 0 | D13: 0 | E13: 0 | F13: 0 | G13: 0 | H13: 0 | I13: 0 | J13: 0 | K13: 0 | L13: 0 | M13: 0 | N13: 0 | O13: 0 | P13: 0 | Q13: 0 | R13: 0 | S13: 0 | T13: 0 | U13: 0
A17: T9. PART TIME Teaching Staff by Highest Qualification and Sex
A18: SDG 4.c.1 Min. qualified | B18: SDG 4.c.2/4.c.4 Pupil-teacher ratios | C18: SDG 4.c.3 % qualified by institution type | D18: SDG 4.c.5 Salary data in Finance sheet | E18: SDG 4.c.6 Attrition in Staff Profile | F18: SDG 4.c.7 CPD training in Staff Profile
A19: Division | B19: Ph.D | D19: Masters Degree | F19: Post Grad. Diploma | H19: Bachelors Degree | J19: Associate Degree | L19: Diploma | N19: Certificate | P19: CAPE/A-Levels | R19: Total M | S19: Total F | T19: Total Trained M | U19: Total Trained F
B20: M | C20: F | D20: M | E20: F | F20: M | G20: F | H20: M | I20: F | J20: M | K20: F | L20: M | M20: F | N20: M | O20: F | P20: M | Q20: F
A21: Division … | B21: 0 | C21: 0 | D21: 0 | E21: 0 | F21: 0 | G21: 0 | H21: 0 | I21: 0 | J21: 0 | K21: 0 | L21: 0 | M21: 0 | N21: 0 | O21: 0 | P21: 0 | Q21: 0 | R21: 0 | S21: 0 | T21: 0 | U21: 0
A22: Division … | B22: 0 | C22: 0 | D22: 0 | E22: 0 | F22: 0 | G22: 0 | H22: 0 | I22: 0 | J22: 0 | K22: 0 | L22: 0 | M22: 0 | N22: 0 | O22: 0 | P22: 0 | Q22: 0 | R22: 0 | S22: 0 | T22: 0 | U22: 0
A23: Division … | B23: 0 | C23: 0 | D23: 0 | E23: 0 | F23: 0 | G23: 0 | H23: 0 | I23: 0 | J23: 0 | K23: 0 | L23: 0 | M23: 0 | N23: 0 | O23: 0 | P23: 0 | Q23: 0 | R23: 0 | S23: 0 | T23: 0 | U23: 0
A24: Total | B24: 0 | C24: 0 | D24: 0 | E24: 0 | F24: 0 | G24: 0 | H24: 0 | I24: 0 | J24: 0 | K24: 0 | L24: 0 | M24: 0 | N24: 0 | O24: 0 | P24: 0 | Q24: 0 | R24: 0 | S24: 0 | T24: 0 | U24: 0

Sheet Staff Profile
A1: T10. TEACHING STAFF PROFILE — Individual Records
A2: SDG 4.c.1 — Qualifications | SDG 4.c.6 — Attrition | SDG 4.c.7 — CPD in-service training (past 12 months)
A3: Complete one row per staff member. CPD hours are required for SDG 4.c.7.
A6: SDG 4.c.1 Qualification | B6: SDG 4.c.6 Attrition | C6: SDG 4.c.7 CPD Hours ★ REQUIRED | D6: SDG 4.c.5 Salary grade for ratio calc
A7: No. | B7: Surname | C7: First Name | D7: Sex | E7: Classification (PR/VP/HOD/TT) | F7: Teacher Type | G7: Subject(s) Taught | H7: Total Periods Taught | I7: Years Teaching Experience | J7: Date of Birth (DD-MMM-YYYY) | K7: Nationality | L7: Highest Qualification | M7: Area of Specialisation | N7: CPD Hours Past Year [SDG 4.c.7] | O7: Appraised Last Year? (Y/N) | P7: Left Service This Year? [SDG 4.c.6]
A8: e.g. | B8: Alexander | C8: Jane | D8: F | E8: HOD | F8: TT | G8: Spanish | H8: 35 | I8: 12 | J8: 29-Aug-2000 | K8: GND | L8: BSc | M8: Computing | N8: 16 | O8: No | P8: No
A9: 1
A10: 2
A11: 3
A12: 4
A13: 5
A14: 6
A15: 7
A16: 8
A17: 9
A18: 10
A19: 11
A20: 12
... A58: 50

Sheet Exams
A1: T11–T12. EXAMINATION RESULTS AND CVQ RESULTS
A2: SDG 4.3.2 — Completion and graduation data feeds GER | SDG 4.3.3 — CVQ results (TVET) | F2: SDG 4.c.x — Teachers/CPD | G2: SDG 4.a.1 — Facilities
A6: T11. Examination Results — Previous Academic Year
A7: SDG 4.3.2 Completion & GER | B7: SDG 4.5.1 Gender parity
A8: Division | B8: Level of Qualification | C8: No. Sat M | D8: No. Sat F | E8: No. Passed M | F8: No. Passed F
A9: Division of … | B9: CAPE | C9: 0 | D9: 0 | E9: 0 | F9: 0
A10: Division of … | B10: Certificate | C10: 0 | D10: 0 | E10: 0 | F10: 0
A11: Division of … | B11: Diploma | C11: 0 | D11: 0 | E11: 0 | F11: 0
A12: Division of … | B12: Associate Degree | C12: 0 | D12: 0 | E12: 0 | F12: 0
A13: Division of … | B13: Degree | C13: 0 | D13: 0 | E13: 0 | F13: 0
A14: Division of … | B14: Masters | C14: 0 | D14: 0 | E14: 0 | F14: 0
A15: Division of … | B15: PhD | C15: 0 | D15: 0 | E15: 0 | F15: 0
A17: T12. CVQ Results — Previous Academic Year
A18: SDG 4.3.3 TVET CVQ Results | B18: SDG 4.5.1 Gender parity
A19: Type | B19: Level | C19: No. Sat M | D19: No. Sat F | E19: No. Passed M | F19: No. Passed F
A20: CVQs | B20: Level 1 | C20: 0 | D20: 0 | E20: 0 | F20: 0
A21: CVQs | B21: Level 2 | C21: 0 | D21: 0 | E21: 0 | F21: 0
A22: CVQs | B22: Level 3 | C22: 0 | D22: 0 | E22: 0 | F22: 0
A23: CVQs | B23: Level 4 | C23: 0 | D23: 0 | E23: 0 | F23: 0
A24: CVQs | B24: Level 5 | C24: 0 | D24: 0 | E24: 0 | F24: 0

Sheet Finance
A1: T13–T15. FINANCE, FACILITIES (WATER AND SANITATION)
A2: SDG 4.5.3 — Equity funding mechanism | SDG 4.5.4 — Expenditure per student | SDG 4.5.6 — Expenditure as % of GDP | SDG 4.c.5 — Teacher salary ratio | SDG 4.a.1 — Water and sanitation | E2: SDG 4.b.1 — ODA/Scholarships | F2: SDG 4.c.x — Teachers/CPD | G2: SDG 4.a.1 — Facilities
A6: T13. Revenue and Recurrent Expenditure — Previous Year 2024–2025
A7: SDG 4.5.4 Expenditure per student | B7: SDG 4.5.6 Expenditure as % GDP | C7: SDG 4.c.5 Teacher salary relative ratio | D7: SDG 4.5.3 Equity funding mechanism
A8: REVENUE | B8: Amount (Local Currency) | C8: RECURRENT EXPENDITURE | D8: Amount (Local Currency)
A9: Government | C9: Personal Emoluments (Total)
A10: Private | C10: - Teaching Staff
A11: Student Fees | C11: - Non-Teaching Staff
A12: Fund Raising Activities | C12: Wages
A13: Grants | C13: Utilities
A14: Sale of Services and Products | C14: Supplies and Materials
A15: Revenue from Consultancy | C15: Operating and Maintenance
A16: Others (Specify) | C16: Office and General
C17: Training
C18: Travel, Subsistence and Allowance
C19: Others (Specify)
A20: TOTAL | C20: TOTAL
A22: SDG 4.5.3 — Equity Funding Mechanism (NEW ITEM)
A23: SDG 4.5.3 Equity funding mechanism
A24: Does the institution have a formal mechanism to reallocate resources to disadvantaged students? | B24: Yes ☐ No ☐
A25: If yes, describe the mechanism (bursaries, subsidised fees, targeted grants, etc.):
A26: What is the total value of equity-targeted funding in the previous academic year (Local Currency)?
A28: SDG 4.c.5 — Average Teacher Salary Relative to Other Professions (NEW ITEM)
A29: SDG 4.c.5 Teacher salary relative ratio
A30: Average annual salary of full-time teaching staff (Local Currency): | B30: 0
A31: Average annual salary of professions requiring comparable qualifications (e.g. civil service graduate grade) (Local Currency): | B31: 0
A32: Ratio (teacher salary ÷ comparator salary — calculated automatically): | B32: 0
A34: T14. Availability of Water — SDG 4.a.1
A35: SDG 4.a.1 Water & Sanitation
A36: Yes = piped, protected well/spring, rainwater, delivered/packaged water | B36: No = unprotected well/spring, lake/river, none
A38: Water currently available from the source | B38: Yes ☐ | C38: No ☐
A39: Accessible handwashing facilities | B39: Yes ☐ | C39: No ☐
A40: Handwashing with soap and water currently available | B40: Yes ☐ | C40: No ☐
A42: T15. Sanitation and Hygiene — SDG 4.a.1
A43: Male Staff Toilets | B43: 0
A44: Female Staff Toilets | B44: 0
A45: Staff Urinals | B45: 0
A46: Female-Students-Only Toilets | B46: 0
A47: Male-Students-Only Toilets | B47: 0
A48: Common Use Toilets | B48: 0
...
